{
  "schema_version": "1.2.0",
  "id": "GHSA-62xg-239j-vxg7",
  "modified": "2022-05-02T04:00:27Z",
  "published": "2022-05-02T04:00:27Z",
  "aliases": [
    "CVE-2009-5011"
  ],
  "details": "Race condition in the FTPHandler class in ftpserver.py in pyftpdlib before 0.5.2 allows remote attackers to cause a denial of service (daemon outage) by establishing and then immediately closing a TCP connection, leading to the getpeername function having an ENOTCONN error, a different vulnerability than CVE-2010-3494.",
  "severity": [

  ],
  "affected": [

  ],
  "references": [
    {
      "type": "ADVISORY",
      "url": "https://nvd.nist.gov/vuln/detail/CVE-2009-5011"
    },
    {
      "type": "WEB",
      "url": "http://code.google.com/p/pyftpdlib/issues/detail?id=100"
    },
    {
      "type": "WEB",
      "url": "http://code.google.com/p/pyftpdlib/source/browse/trunk/HISTORY"
    },
    {
      "type": "WEB",
      "url": "http://code.google.com/p/pyftpdlib/source/detail?r=543"
    },
    {
      "type": "WEB",
      "url": "http://code.google.com/p/pyftpdlib/source/diff?spec=svn543&r=543&format=side&path=/trunk/pyftpdlib/ftpserver.py"
    }
  ],
  "database_specific": {
    "cwe_ids": [
      "CWE-362"
    ],
    "severity": "MODERATE",
    "github_reviewed": false
  }
}