{
  "schema_version": "1.2.0",
  "id": "GHSA-62xg-239j-vxg7",
  "modified": "2022-06-17T22:28:38Z",
  "published": "2022-05-02T04:00:27Z",
  "aliases": [
    "CVE-2009-5011"
  ],
  "summary": "Concurrent Execution using Shared Resource with Improper Synchronization ('Race Condition') in pyftpdlib",
  "details": "Race condition in the FTPHandler class in ftpserver.py in pyftpdlib before 0.5.2 allows remote attackers to cause a denial of service (daemon outage) by establishing and then immediately closing a TCP connection, leading to the getpeername function having an ENOTCONN error, a different vulnerability than CVE-2010-3494.",
  "severity": [

  ],
  "affected": [
    {
      "package": {
        "ecosystem": "PyPI",
        "name": "pyftpdlib"
      },
      "ranges": [
        {
          "type": "ECOSYSTEM",
          "events": [
            {
              "introduced": "0"
            },
            {
              "fixed": "0.5.2"
            }
          ]
        }
      ],
      "database_specific": {
        "last_known_affected_version_range": "<= 0.5.1"
      }
    }
  ],
  "references": [
    {
      "type": "ADVISORY",
      "url": "https://nvd.nist.gov/vuln/detail/CVE-2009-5011"
    },
    {
      "type": "WEB",
      "url": "http://code.google.com/p/pyftpdlib/issues/detail?id=100"
    },
    {
      "type": "PACKAGE",
      "url": "https://github.com/giampaolo/pyftpdlib"
    }
  ],
  "database_specific": {
    "cwe_ids": [
      "CWE-362"
    ],
    "severity": "MODERATE",
    "github_reviewed": true
  }
}