{
  "schema_version": "1.2.0",
  "id": "GHSA-2xqv-jq2p-7rr6",
  "modified": "2022-04-05T00:00:22Z",
  "published": "2022-04-05T00:00:22Z",
  "aliases": [
    "CVE-2021-33010"
  ],
  "details": "An exception is thrown from a function in AVEVA System Platform versions 2017 through 2020 R2 P01, but it is not caught, which may cause a denial-of-service condition.",
  "severity": [

  ],
  "affected": [

  ],
  "references": [
    {
      "type": "ADVISORY",
      "url": "https://nvd.nist.gov/vuln/detail/CVE-2021-33010"
    },
    {
      "type": "WEB",
      "url": "https://www.aveva.com/content/dam/aveva/documents/support/cyber-security-updates/SecurityBulletin_AVEVA-2021-002.pdf"
    },
    {
      "type": "WEB",
      "url": "https://www.cisa.gov/uscert/ics/advisories/icsa-21-180-05"
    }
  ],
  "database_specific": {
    "cwe_ids": [

    ],
    "severity": null,
    "github_reviewed": false
  }
}